Workbook

Sheet Form Responses 2
A1: Timestamp | B1: Pertanyaan Tanpa Judul | C1: Merged Doc ID - TLC Scanner (Densitometer) | D1: Merged Doc URL - TLC Scanner (Densitometer) | E1: Link to merged Doc - TLC Scanner (Densitometer) | F1: Document Merge Status - TLC Scanner (Densitometer)

Sheet TARIF LAYANAN
A1: LAMPIRAN TARIF LAYANAN PENUNJANG AKADEMIK
A2: UNIVERSITAS SEBELAS MARET
A3: UPT LABORATORIUM TERPADU
A5: No. | B5: JENIS LAYANAN | G5: SATUAN | H5: TARIF (Rp)
A6: 1 | B6: LAYANAN PENGUJIAN KUALITAS AIR PER PARAMETER
B7: 1 | C7: Chemical Oxygen Demand (COD) | G7: Per sampel | H7: 100000
B8: 2 | C8: Biological Oxygen Demand (BOD) | G8: Per sampel | H8: 140000
B9: 3 | C9: Sulfida (S) | G9: Per sampel | H9: 150000
B10: 4 | C10: Sianida (CN) | G10: Per sampel | H10: 350000
B11: 5 | C11: Phenol | G11: Per sampel | H11: 300000
B12: 6 | C12: Dissolved Oxygen (DO) | G12: Per sampel | H12: 50000
B13: 7 | C13: Total Padatan Tersuspensi (TSS) | G13: Per sampel | H13: 100000
B14: 8 | C14: Total Padatan Terlarut (TDS) | G14: Per sampel | H14: 100000
B15: 9 | C15: Nitrit (NO2-N) | G15: Per sampel | H15: 90000
B16: 10 | C16: Nitrat (NO3-N) | G16: Per sampel | H16: 90000
B17: 11 | C17: Amonia Total (NH3-N) | G17: Per sampel | H17: 110000
B18: 12 | C18: orto-Phosphat (PO4) | G18: Per sampel | H18: 100000
... B54: 48 | C54: Perak (Ag) | G54: Per sampel | H54: 100000
A55: 2 | B55: LAYANAN PENGUJIAN KUALITAS UDARA PER PARAMETER
B56: 1 | C56: Ozon (O3) | G56: Per sampel | H56: 100000
B57: 2 | C57: Hidrogen sulfida (H2S) | G57: Per sampel | H57: 100000
B58: 3 | C58: Timbal (Pb) | G58: Per sampel | H58: 200000
B59: 4 | C59: Partikel tersuspensi total (TSP) | G59: Per sampel | H59: 200000
B60: 5 | C60: Amonia (NH3) | G60: Per sampel | H60: 150000
B61: 6 | C61: Carbon monoksida (CO) | G61: Per sampel | H61: 90000
B62: 7 | C62: Sulfur dioksida (SO2) | G62: Per sampel | H62: 150000
B63: 8 | C63: Nitrogen dioksida (NO2) | G63: Per sampel | H63: 100000
B65: Layanan pengujian Kebisingan
B66: 1 | C66: Tingkat kebisingan lingkungan | G66: Per sampel | H66: 100000
B67: Layanan pengujian lingkungan kerja
B68: 1 | C68: Intensitas pencahayaan | G68: Per sampel | H68: 100000
A70: 3 | B70: PENGUJIAN PARAMETER HALAL
B71: 1. | C71: Analisis DNA sd PCR | G71: Per sampel | H71: 600000
B72: 2. | C72: Analisis Alkohol kualitatif | G72: Per sampel | H72: 300000
B73: 3. | C73: Analisis Alkohol kuantitatif | G73: Per sampel | H73: 300000
A75: 4 | B75: PENGUJIAN PRODUK
B76: 1. | C76: Analisis APD (kain masker, kain hazmat)
C77: 1 | D77: Uji Anti bakteri APD | G77: Per sampel | H77: 500000
C78: 2 | D78: Uji kedap air APD | G78: Per sampel | H78: 150000
C79: 3 | D79: Uji kedap udara APD | G79: Per sampel | H79: 150000
...

Sheet TARIF LAYANAN 2025
A2: UNIVERSITAS SEBELAS MARET
A3: UPT LABORATORIUM TERPADU
A5: NO | B5: JENIS LAYANAN | G5: SATUAN | H5: TARIF (Rp) | I5: KETERANGAN
A6: 1 | B6: LAYANAN PENGUJIAN KUALITAS AIR PER PARAMETER
B7: 1 | C7: Chemical Oxygen Demand (COD) | G7: Per sampel | H7: 100000
B8: 2 | C8: Biological Oxygen Demand (BOD) | G8: Per sampel | H8: 140000
B9: 3 | C9: Sulfida (S) | G9: Per sampel | H9: 150000
B10: 4 | C10: Sianida (CN) | G10: Per sampel | H10: 350000
B11: 5 | C11: Phenol | G11: Per sampel | H11: 300000
B12: 6 | C12: Dissolved Oxygen (DO) | G12: Per sampel | H12: 50000
B13: 7 | C13: Total Padatan Tersuspensi (TSS) | G13: Per sampel | H13: 100000
B14: 8 | C14: Total Padatan Terlarut (TDS) | G14: Per sampel | H14: 100000
B15: 9 | C15: Nitrit (NO2-N) | G15: Per sampel | H15: 90000
B16: 10 | C16: Nitrat (NO3-N) | G16: Per sampel | H16: 90000
B17: 11 | C17: Amonia Total (NH3-N) | G17: Per sampel | H17: 110000
B18: 12 | C18: orto-Phosphat (PO4) | G18: Per sampel | H18: 100000
... B56: 50 | C56: Perak (Ag) | G56: Per sampel | H56: 100000
A58: 2 | B58: LAYANAN PENGUJIAN KUALITAS UDARA PER PARAMETER
B59: 1 | C59: Ozon (O3) | G59: Per sampel | H59: 100000
B60: 2 | C60: Hidrogen sulfida (H2S) | G60: Per sampel | H60: 100000
B61: 3 | C61: Timbal (Pb) | G61: Per sampel | H61: 200000
B62: 4 | C62: Partikel tersuspensi total (TSP) | G62: Per sampel | H62: 200000
B63: 5 | C63: Amonia (NH3) | G63: Per sampel | H63: 150000 | K63: Karena bahan yang digunakan berbeda dengan uji kualitas Air. Dalam tahun yang sama pembuatan tarif penggunaan bahan di udara lebih mahal dari penggunaan bahan untuk air.
B64: 6 | C64: Carbon monoksida (CO) | G64: Per sampel | H64: 90000
B65: 7 | C65: Sulfur dioksida (SO2) | G65: Per sampel | H65: 150000
B66: 8 | C66: Nitrogen dioksida (NO2) | G66: Per sampel | H66: 100000
B68: Layanan pengujian Kebisingan
B69: 1 | C69: Tingkat kebisingan lingkungan | G69: Per sampel | H69: 100000
B70: Layanan pengujian lingkungan kerja
B71: 1 | C71: Intensitas pencahayaan | G71: Per sampel | H71: 100000
A73: 3 | B73: PENGUJIAN PARAMETER HALAL
B74: 1. | C74: Analisis DNA sd PCR | G74: Per sampel | H74: 600000
B75: 2. | C75: Analisis Alkohol kualitatif | G75: Per sampel | H75: 300000
B76: 3. | C76: Analisis Alkohol kuantitatif | G76: Per sampel | H76: 300000
A78: 4 | B78: PENGUJIAN PRODUK
B79: 1. | C79: Analisis APD (kain masker, kain hazmat)
C80: 1 | D80: Uji Anti bakteri APD | G80: Per sampel | H80: 500000
C81: 2 | D81: Uji kedap air APD | G81: Per sampel | H81: 150000
C82: 3 | D82: Uji kedap udara APD | G82: Per sampel | H82: 150000
B84: 2. | C84: Analisis Madu
...

Sheet Harga Bahan
A1: LAMPIRAN TARIF Bahan
A2: UNIVERSITAS SEBELAS MARET
A3: UPT LABORATORIUM TERPADU
A5: No. | B5: Nama Bahan | C5: Cat. | D5: Satuan | E5: Harga Satuan
A6: 1 | B6: n-Hexane | D6: ml | E6: 1000
A7: 2 | B7: ethanol | D7: ml | E7: 1000
A8: 3 | B8: ethyl acetate | D8: ml
A9: 4 | B9: Glacial Acetic Acid | D9: mL | E9: 1000

Sheet Bahan
A1: Hari, Tanggal pembuatan rekap | B1: Pembuat Rekap | C1: Agenda | D1: Nama | E1: NIM | F1: Jurusan/ Fakultas/Univ | G1: Nama Bahan 1 | H1: Jml 1 | I1: Sat 1 | J1: Harga Sat 1 | K1: Harga 1 | L1: Nama Bahan 2 | M1: Jumlah Bahan 2 | N1: Satuan 2 | O1: Harga Satuan 2 | P1: Harga 2 | Q1: Nama Bahan 3 | R1: Jumlah Bahan 3 | S1: Satuan 3 | T1: Harga Satuan 3 | U1: Harga 3 | V1: Nama Bahan 4 | W1: Jumlah Bahan 4 | X1: Satuan 4 | Y1: Harga Satuan 4 | Z1: Harga 4 | AA1: Nama Bahan 5 | AB1: Jumlah Bahan 5 | AC1: Satuan 5 | AD1: Harga Satuan 5 | AE1: Harga 5 | AF1: Nama Bahan 6 | AG1: Jumlah Bahan 6 | AH1: Satuan 6 | AI1: Harga Satuan 6 | AJ1: Harga 6 | AK1: Nama Bahan 7 | AL1: Jumlah Bahan 7 | AM1: Satuan 7 | AN1: Harga Satuan 7 | AO1: Harga 7 | AP1: Nama Bahan 8 | AQ1: Jumlah Bahan 8 | AR1: Satuan 8 | AS1: Harga Satuan 8 | AT1: Harga 8 | AU1: Nama Bahan 9 | AV1: Jumlah Bahan 9 | AW1: Satuan 9 | AX1: Harga Satuan 9 | AY1: Harga 9 | AZ1: Total Harga | BA1: Merged Doc ID - Pembelian Bahan | BB1: Link to merged Doc - Pemakaian Bahan | BC1: Document Merge Status - Pemakaian Bahan | BD1: Merged Doc URL - Pembelian Bahan | BE1: Link to merged Doc - Pembelian Bahan | BF1: Document Merge Status - Pembelian Bahan | BG1: Merged Doc ID - Pemakaian Bahan | BH1: Merged Doc ID - Kuitansi bahan | BI1: Merged Doc URL - Kuitansi bahan | BJ1: Link to merged Doc - Kuitansi bahan | BK1: Document Merge Status - Kuitansi bahan
D2: Adelia Shabeila Gumitha | E2: N16231161 | F2: D4 Analis Kesehatan/Ilmu Kesehatan | G2: Media PDA | H2: 31.2 | I2: gr | L2: Alkohol 96% | M2: 20 | N2: ml | Q2: Kristal Violet | R2: 10 | S2: ml | V2: Iodine | W2: 10 | X2: ml | AA2: Safranin | AB2: 10 | AC2: ml | BH2: 1j3Wq84eEGAML_cJ2WAvg1SiRfeQHYh4F | BI2: https://drive.google.com/file/d/1j3Wq84eEGAML_cJ2WAvg1SiRfeQHYh4F/view?usp=drivesdk | BJ2: =HYPERLINK("https://drive.google.com/file/d/1j3Wq84eEGAML_cJ2WAvg1SiRfeQHYh4F/view?usp=drivesdk","Bahan Adelia Shabeila Gumitha") -> Bahan Adelia Shabeila Gumitha | BK2: Document successfully created; Document successfully merged; PDF created; Manually run by labterpadu.unit.uns@gmail.com; Timestamp: Feb 19 2025 2:07 AM
A3: 45707 | B3: Retno H | D3: Novanda Wisnu Ardhana | E3: H07201227 | F3: FP | G3: Nutrien Agar | H3: 20 | I3: gr | J3: 6000 | K3: =H3*J3 -> 120000 | AZ3: =K3+P3+Z3+AE3+AJ3+AO3+AT3+AY3 -> 120000 | BH3: 1fNmCb1en7iEqUtKoB7d0bDv7RW4Wb5HC | BI3: https://drive.google.com/file/d/1fNmCb1en7iEqUtKoB7d0bDv7RW4Wb5HC/view?usp=drivesdk | BJ3: =HYPERLINK("https://drive.google.com/file/d/1fNmCb1en7iEqUtKoB7d0bDv7RW4Wb5HC/view?usp=drivesdk","Bahan Novanda Wisnu Ardhana") -> Bahan Novanda Wisnu Ardhana | BK3: Document successfully created; Document successfully merged; PDF created; Manually run by labterpadu.unit.uns@gmail.com; Timestamp: Feb 19 2025 2:07 AM
B4: Retno H | D4: Veronika Adien | E4: H0921091 | F4: ITP | G4: MHA | H4: 57 | I4: gr | J4: 7000 | K4: =H4*J4 -> 399000 | AZ4: =K4+P4+Z4+AE4+AJ4+AO4+AT4+AY4 -> 399000 | BH4: 1xIZgW6zqK4QK220PwLOMa1TCo2rqyefN | BI4: https://drive.google.com/file/d/1xIZgW6zqK4QK220PwLOMa1TCo2rqyefN/view?usp=drivesdk | BJ4: =HYPERLINK("https://drive.google.com/file/d/1xIZgW6zqK4QK220PwLOMa1TCo2rqyefN/view?usp=drivesdk","Bahan Veronika Adien ") -> Bahan Veronika Adien | BK4: Document successfully created; Document successfully merged; PDF created; Manually run by labterpadu.unit.uns@gmail.com; Timestamp: May 6 2025 9:22 PM
B5: Retno H | D5: Jasmine Aderia | E5: H0921032 | F5: ITP | G5: NaCl | H5: 0.9 | I5: gr | J5: 3000 | K5: =H5*J5 -> 2700 | L5: Blank Disc | M5: 56 | N5: pcs | O5: 10000 | P5: =O5*M5 -> 560000 | AZ5: =K5+P5+Z5+AE5+AJ5+AO5+AT5+AY5 -> 562700 | BH5: 1gsmso5lws4njxwYzaH4gqv8A_pj0woaD | BI5: https://drive.google.com/file/d/1gsmso5lws4njxwYzaH4gqv8A_pj0woaD/view?usp=drivesdk | BJ5: =HYPERLINK("https://drive.google.com/file/d/1gsmso5lws4njxwYzaH4gqv8A_pj0woaD/view?usp=drivesdk","Bahan Jasmine Aderia") -> Bahan Jasmine Aderia | BK5: Document successfully created; Document successfully merged; PDF created; Manually run by labterpadu.unit.uns@gmail.com; Timestamp: May 6 2025 9:46 PM
B6: Retno H | D6: Rahma Isnaini Puji Astuti | E6: K4321066 | F6: P Biologi/FKIP/UNS | G6: BOD Seed | H6: 1 | I6: kapsul | J6: 90000 | K6: =H6*J6 -> 90000 | L6: H2SO4 | M6: 50 | N6: ml | O6: 1000 | P6: =O6*M6 -> 50000 | Q6: Ag2SO4 | R6: 1 | S6: gr | T6: 90000 | U6: =T6*R6 -> 90000 | V6: Laruatan pereaksi asam | W6: 32 | X6: ml | Y6: 1500 | Z6: =Y6*W6 -> 48000 | AA6: Larutan pencerna rendah | AB6: 14 | AC6: ml | AD6: 1000 | AE6: =AD6*AB6 -> 14000 | AZ6: =K6+P6+U6+Z6+AE6+AJ6+AO6+AT6+AY6 -> 292000 | BH6: 1jIziFdUeycqHguSGINsbst-b4X0N4urB | BI6: https://drive.google.com/file/d/1jIziFdUeycqHguSGINsbst-b4X0N4urB/view?usp=drivesdk | BJ6: =HYPERLINK("https://drive.google.com/file/d/1jIziFdUeycqHguSGINsbst-b4X0N4urB/view?usp=drivesdk","Bahan Rahma Isnaini Puji Astuti") -> Bahan Rahma Isnaini Puji Astuti | BK6: Document successfully created; Document successfully merged; PDF created; Manually run by labterpadu.unit.uns@gmail.com; Timestamp: Jul 21 2025 12:09 AM
B7: Retno H | D7: Aura | E7: J520220074 | F7: FKG/UMS | G7: Glacial Acetic Acid | H7: 10 | I7: mL | J7: 1000 | K7: 10000 | AZ7: 10000 | BH7: 1d33UQqpy93u3uYf_kB_bwp24A0g07lPW | BI7: https://drive.google.com/file/d/1d33UQqpy93u3uYf_kB_bwp24A0g07lPW/view?usp=drivesdk | BJ7: =HYPERLINK("https://drive.google.com/file/d/1d33UQqpy93u3uYf_kB_bwp24A0g07lPW/view?usp=drivesdk","Bahan Aura") -> Bahan Aura | BK7: Document successfully created; Document successfully merged; PDF created; Manually run by labterpadu.unit.uns@gmail.com; Timestamp: Aug 24 2025 11:22 PM
B8: Retno H | D8: Debby Wulan Purnama | E8: H0222031 | F8: FP | G8: Mercury Chloride | H8: 2 | I8: gr | J8: 25000 | AZ8: 50000 | BH8: 14uFk-hsJf63XZ_DyLUqf6cNg5KInyzjS | BI8: https://drive.google.com/file/d/14uFk-hsJf63XZ_DyLUqf6cNg5KInyzjS/view?usp=drivesdk | BJ8: =HYPERLINK("https://drive.google.com/file/d/14uFk-hsJf63XZ_DyLUqf6cNg5KInyzjS/view?usp=drivesdk","Bahan Debby Wulan Purnama") -> Bahan Debby Wulan Purnama | BK8: Document successfully created; Document successfully merged; PDF created; Manually run by labterpadu.unit.uns@gmail.com; Timestamp: Sep 11 2025 3:27 AM
A9: 45940 | B9: Retno H | D9: Nur Laila | F9: FP | G9: LB | H9: 60 | I9: gr | J9: 5000 | K9: 300000 | L9: BGLB | M9: 243.6 | N9: g | O9: 4300 | P9: 1047480 | Q9: EMBA | R9: 85 | S9: 9 | T9: 5800 | U9: 493000 | AZ9: =K9+P9+U9 -> 1840480 | BH9: 1X9NhmzJiMke9g2uVZroxZZLqrTSBz4Eu | BI9: https://drive.google.com/file/d/1X9NhmzJiMke9g2uVZroxZZLqrTSBz4Eu/view?usp=drivesdk | BJ9: =HYPERLINK("https://drive.google.com/file/d/1X9NhmzJiMke9g2uVZroxZZLqrTSBz4Eu/view?usp=drivesdk","Bahan Nur Laila") -> Bahan Nur Laila | BK9: Document successfully created; Document successfully merged; PDF created; Manually run by labterpadu.unit.uns@gmail.com; Timestamp: Oct 10 2025 12:29 AM

Sheet A

Sheet Uji gabungan
A1: Tanggal Map Keluar | B1: Hari, Tanggal pembuatan rekap | C1: Pengujian | D1: Agenda | E1: Nama | F1: NIM/NIP | G1: Fakultas/Univ | H1: Akses Lab | I1: Jumlah Sampel | J1: Uji 1 | K1: Analis1 | L1: Harga_Uji1 | M1: Harga_1 | N1: Uji 2 | O1: Analis2 | P1: Harga_Uji2 | Q1: Harga_2 | R1: Uji 3 | S1: Analsi3 | T1: Harga_Uji3 | U1: Harga_3 | V1: Uji 4 | W1: Analis4 | X1: Harga_Uji4 | Y1: Harga_4 | Z1: Uji 5 | AA1: Analis5 | AB1: Harga_Uji5 | AC1: Harga_5 | AD1: TotalHarga | AE1: Pembuat Rekap | AF1: Merged Doc ID - Uji gabungan | AG1: Merged Doc URL - Uji gabungan | AH1: Link to merged Doc - Uji gabungan | AI1: Document Merge Status - Uji gabungan
A2: Rabu, 24 Septenber 2025 | B2: 45947 | C2: Viskositas, ALT, Homogenitas, berat jenis, pH | D2: 628 | E2: Suyono | F2: - | G2: SMA N 1 Toroh | H2: Tidak Akses | I2: 1 | J2: Viskositas | K2: Agus W | L2: 75000 | M2: =$I$2*L2 -> 75000 | N2: ALT | O2: Galuh Pratiwi | P2: 200000 | Q2: =$I$2*P2 -> 200000 | R2: Homogenitas | S2: Retno Hartati | T2: 50000 | U2: =$I$2*T2 -> 50000 | V2: Berat jenis | W2: Retno Hartati | X2: 50000 | Y2: =$I$2*X2 -> 50000 | Z2: pH (pH stik) | AA2: Retno Hartati | AB2: 15000 | AC2: =$I$2*AB2 -> 15000 | AD2: =M2+Q2+U2+Y2+AC2 -> 390000 | AE2: Retno Hartati | AF2: 1fM5cmc6il8KMDpSkDUz3kglKO-JV-wNi | AG2: https://drive.google.com/file/d/1fM5cmc6il8KMDpSkDUz3kglKO-JV-wNi/view?usp=drivesdk | AH2: =HYPERLINK("https://drive.google.com/file/d/1fM5cmc6il8KMDpSkDUz3kglKO-JV-wNi/view?usp=drivesdk","Uji Gabungan 628") -> Uji Gabungan 628 | AI2: Document successfully created; Document successfully merged; PDF created; Manually run by labterpadu.unit.uns@gmail.com; Timestamp: Oct 17 2025 3:43 AM
A3: 45929 | B3: 45947 | C3: Protein, kadar air | D3: 641 | E3: Hafidz Praba Harjono | F3: 24236 | G3: SMA N 4 Surakarta | H3: Tidak Akses | I3: 8 | J3: Protein | K3: Widyan, Zahra | L3: 150000 | M3: =$I$3*L3 -> 1200000 | N3: Kadar air | O3: Galuh Pratiwi | P3: 100000 | Q3: =$I$3*P3 -> 800000 | AD3: =M3+Q3+U3+Y3+AC3 -> 2000000 | AE3: Retno Hartati | AF3: 1S1T6_mGlvJJdVIAit4pprfv3LxmjSMWn | AG3: https://drive.google.com/file/d/1S1T6_mGlvJJdVIAit4pprfv3LxmjSMWn/view?usp=drivesdk | AH3: =HYPERLINK("https://drive.google.com/file/d/1S1T6_mGlvJJdVIAit4pprfv3LxmjSMWn/view?usp=drivesdk","Uji Gabungan 641") -> Uji Gabungan 641 | AI3: Document successfully created; Document successfully merged; PDF created; Manually run by labterpadu.unit.uns@gmail.com; Timestamp: Oct 17 2025 3:58 AM
A4: 45947 | B4: 45947 | C4: Homogenitas, pH | D4: 687 | E4: Wahyu Putri Lestari,M.Pd. | F4: - | G4: - | H4: Tidak Akses | I4: 1 | J4: Homogenitas | K4: Zahra | L4: 50000 | M4: =I4*L4 -> 50000 | N4: pH | O4: Zahra | P4: 50000 | Q4: =$I$4*P4 -> 50000 | AD4: =M4+Q4+U4+Y4+AC4 -> 100000 | AE4: Retno Hartati | AF4: 1Z8pLrjTgOkJCu5FwYY6EoIfdbY-9SEWm | AG4: https://drive.google.com/file/d/1Z8pLrjTgOkJCu5FwYY6EoIfdbY-9SEWm/view?usp=drivesdk | AH4: =HYPERLINK("https://drive.google.com/file/d/1Z8pLrjTgOkJCu5FwYY6EoIfdbY-9SEWm/view?usp=drivesdk","Uji Gabungan 687") -> Uji Gabungan 687 | AI4: Document successfully created; Document successfully merged; PDF created; Manually run by labterpadu.unit.uns@gmail.com; Timestamp: Oct 17 2025 3:59 AM
A5: Rabu, 23 Septenber 2025 | B5: 45967 | C5: Anti Bakteri MIC | D5: 620 | E5: Dessy Natasya | F5: 4311421058 | G5: Univ. Negeri Semarang | H5: Tidak Akses | I5: 51 | J5: Sampel MIC | K5: Pratiwi | L5: 25000 | M5: =I5*L5 -> 1275000 | AD5: =M5+Q5+U5+Y5+AC5 -> 1275000 | AE5: Retno Hartati | AF5: 1_J3w2KBjCnTUSpCEHxL2dyjJW19D8pyK | AG5: https://drive.google.com/file/d/1_J3w2KBjCnTUSpCEHxL2dyjJW19D8pyK/view?usp=drivesdk | AH5: =HYPERLINK("https://drive.google.com/file/d/1_J3w2KBjCnTUSpCEHxL2dyjJW19D8pyK/view?usp=drivesdk","Uji Gabungan 620") -> Uji Gabungan 620 | AI5: Document successfully created; Document successfully merged; PDF created; Manually run by labterpadu.unit.uns@gmail.com; Timestamp: Nov 6 2025 2:07 AM
A6: Rabu, 23 Septenber 2026 | B6: 45967 | C6: Anti Bakteri MIC | D6: 621 | E6: Wildan Arrofi | F6: 4311421078 | G6: Univ. Negeri Semarang | H6: Tidak Akses | I6: 15 | J6: Sampel MIC | K6: Pratiwi | L6: 25000 | M6: =I6*L6 -> 375000 | AD6: =M6+Q6+U6+Y6+AC6 -> 375000 | AE6: Retno Hartati | AF6: 17_hli0vi4KzTK8xNPmFiOqo4-6DKOZaS | AG6: https://drive.google.com/file/d/17_hli0vi4KzTK8xNPmFiOqo4-6DKOZaS/view?usp=drivesdk | AH6: =HYPERLINK("https://drive.google.com/file/d/17_hli0vi4KzTK8xNPmFiOqo4-6DKOZaS/view?usp=drivesdk","Uji Gabungan 621") -> Uji Gabungan 621 | AI6: Document successfully created; Document successfully merged; PDF created; Manually run by labterpadu.unit.uns@gmail.com; Timestamp: Nov 6 2025 2:07 AM
A7: 45921 | B7: 45971 | C7: Protein | D7: 615 | E7: Angelica Kusumaningtyas | F7: 22600017 | G7: Teknologi Pangan/Fakultas Teknologi dan Industri Pangan/Universitas Slamet Riyadi Surakarta | H7: Tidak Akses | I7: 15 | J7: Protein | K7: Widyan, Zahra | L7: 150000 | M7: =I7*L7 -> 2250000 | AD7: =M7+Q7+U7+Y7+AC7 -> 2250000 | AE7: Retno Hartati | AF7: 1ouHjvFXCe_JugbMGkcH1TRCjtdnw0B-W | AG7: https://drive.google.com/file/d/1ouHjvFXCe_JugbMGkcH1TRCjtdnw0B-W/view?usp=drivesdk | AH7: =HYPERLINK("https://drive.google.com/file/d/1ouHjvFXCe_JugbMGkcH1TRCjtdnw0B-W/view?usp=drivesdk","Uji Gabungan 615") -> Uji Gabungan 615 | AI7: Document successfully created; Document successfully merged; PDF created; Manually run by labterpadu.unit.uns@gmail.com; Timestamp: Nov 13 2025 12:36 AM
A8: 45975 | B8: 45982 | C8: Protein | D8: 765 | E8: Ahmad Ananda Daffa Pratama | F8: F0224108 | G8: Manajemen / Ekonomi dan Bisnis / UNS | H8: Tidak Akses | I8: 1 | J8: Protein | K8: Retno | L8: 150000 | M8: =I8*L8 -> 150000 | AD8: =M8+Q8+U8+Y8+AC8 -> 150000 | AE8: Retno Hartati | AF8: 1N7TycLYkagmRjLZJn4Dag_O6E6vPZcYQ | AG8: https://drive.google.com/file/d/1N7TycLYkagmRjLZJn4Dag_O6E6vPZcYQ/view?usp=drivesdk | AH8: =HYPERLINK("https://drive.google.com/file/d/1N7TycLYkagmRjLZJn4Dag_O6E6vPZcYQ/view?usp=drivesdk","Uji Gabungan 765") -> Uji Gabungan 765 | AI8: Document successfully created; Document successfully merged; PDF created; Manually run by labterpadu.unit.uns@gmail.com; Timestamp: Nov 21 2025 2:01 AM

Sheet Regenerasi
A1: Tanggal Map Keluar | B1: Hari, Tanggal pembuatan rekap | C1: Agenda | D1: Nama | E1: NIM/NIP | F1: Fakultas/Univ | G1: Akses Lab | H1: Proses | I1: Analis | J1: Jumlah Sampel | K1: Harga per sampel | L1: Total Harga | M1: Pembuat Rekap | N1: Merged Doc ID - Regenerasi Bakteri | O1: Merged Doc URL - Regenerasi Bakteri | P1: Link to merged Doc - Regenerasi Bakteri | Q1: Document Merge Status - Regenerasi Bakteri
A2: 45726 | B2: 45730 | C2: 156 | D2: Fitria Mayasari | E2: 4211069 | F2: STIKES Nasional | G2: Tidak Akses | H2: Regenerasi Bakteri P aerugenosa | I2: Galuh Pratiwi | J2: 1 | K2: 300000 | L2: =J2*K2 -> 300000 | M2: Retno Hartati | N2: 1EgjzUUyiFNNVGEw4u4e4-vFrnovJKPBV | O2: https://drive.google.com/file/d/1EgjzUUyiFNNVGEw4u4e4-vFrnovJKPBV/view?usp=drivesdk | P2: =HYPERLINK("https://drive.google.com/file/d/1EgjzUUyiFNNVGEw4u4e4-vFrnovJKPBV/view?usp=drivesdk","Regenerasi_Fitria Mayasari") -> Regenerasi_Fitria Mayasari | Q2: Document successfully created; Document successfully merged; PDF created; Manually run by labterpadu.unit.uns@gmail.com; Timestamp: Mar 13 2025 9:52 PM
A3: 45730 | B3: 45734 | C3: 166 | D3: Afifah Ambar Maharani | E3: 4211002 | F3: S1 Farmasi | G3: Tidak Akses | H3: Regenerasi Bakteri S. aureus | I3: Galuh Pratiwi | J3: 1 | K3: 300000 | L3: =J3*K3 -> 300000 | M3: Retno Hartati | N3: 1az1dqMf8Z9wkDk1tfCI0lXptSGLh8GxF | O3: https://drive.google.com/file/d/1az1dqMf8Z9wkDk1tfCI0lXptSGLh8GxF/view?usp=drivesdk | P3: =HYPERLINK("https://drive.google.com/file/d/1az1dqMf8Z9wkDk1tfCI0lXptSGLh8GxF/view?usp=drivesdk","Regenerasi_Afifah Ambar Maharani") -> Regenerasi_Afifah Ambar Maharani | Q3: Document successfully created; Document successfully merged; PDF created; Manually run by labterpadu.unit.uns@gmail.com; Timestamp: Mar 17 2025 9:39 PM
A4: 45737 | B4: 45737 | C4: 176 | D4: Intan Nuraini | E4: M0421028 | F4: FMIPA/Biologi | G4: Akses Lab | H4: Regenerasi Bakteri E.coli | I4: Galuh Pratiwi | J4: 1 | K4: 300000 | L4: =J4*K4 -> 300000 | M4: Retno Hartati | N4: 1_HtZ58MDGsSfsIjaoCkjO7P3I_7sc0iH | O4: https://drive.google.com/file/d/1_HtZ58MDGsSfsIjaoCkjO7P3I_7sc0iH/view?usp=drivesdk | P4: =HYPERLINK("https://drive.google.com/file/d/1_HtZ58MDGsSfsIjaoCkjO7P3I_7sc0iH/view?usp=drivesdk","Regenerasi_Intan Nuraini") -> Regenerasi_Intan Nuraini | Q4: Document successfully created; Document successfully merged; PDF created; Manually run by labterpadu.unit.uns@gmail.com; Timestamp: Mar 20 2025 10:57 PM
A5: 45737 | B5: 45762 | C5: 181 | D5: Veronika Adien Arthamarchia | E5: H0921091 | F5: ITP Pertanian UNS | G5: Akses | H5: Regenerasi Bakteri E.coli | I5: Galuh Pratiwi | J5: 1 | K5: 300000 | L5: =J5*K5 -> 300000 | M5: Retno Hartati | N5: 1_lkezOOvx2TrYkdLPU3hmeMJDAkn8iw2 | O5: https://drive.google.com/file/d/1_lkezOOvx2TrYkdLPU3hmeMJDAkn8iw2/view?usp=drivesdk | P5: =HYPERLINK("https://drive.google.com/file/d/1_lkezOOvx2TrYkdLPU3hmeMJDAkn8iw2/view?usp=drivesdk","Regenerasi_Veronika Adien Arthamarchia") -> Regenerasi_Veronika Adien Arthamarchia | Q5: Document successfully created; Document successfully merged; PDF created; Manually run by labterpadu.unit.uns@gmail.com; Timestamp: Apr 14 2025 10:35 PM
A6: 45737 | B6: 45762 | C6: 182 | D6: Jasmine Aderia | E6: H0921032 | F6: ITP Pertanian UNS | G6: Akses | H6: Regenerasi Bakteri S.aureus | I6: Galuh Pratiwi | J6: 1 | K6: 300000 | L6: =J6*K6 -> 300000 | M6: Retno Hartati | N6: 1p_7d7Ep0UDGgGJIR32PN2KG_kC5EV934 | O6: https://drive.google.com/file/d/1p_7d7Ep0UDGgGJIR32PN2KG_kC5EV934/view?usp=drivesdk | P6: =HYPERLINK("https://drive.google.com/file/d/1p_7d7Ep0UDGgGJIR32PN2KG_kC5EV934/view?usp=drivesdk","Regenerasi_Jasmine Aderia") -> Regenerasi_Jasmine Aderia | Q6: Document successfully created; Document successfully merged; PDF created; Manually run by labterpadu.unit.uns@gmail.com; Timestamp: Apr 14 2025 10:42 PM
A7: 45820 | B7: 45820 | C7: 385 | D7: Wardah Radhwa Hafizhah | E7: M0421077 | F7: Biologi / FMIPA / UNS | G7: Tidak Akses | H7: Regenerasi Bakteri S.aureus | I7: Galuh Pratiwi | J7: 1 | K7: 300000 | L7: =J7*K7 -> 300000 | M7: Retno Hartati | N7: 1Zv721vZXAzVEpZ1RDg4c_Jd7DHyqBdZD | O7: https://drive.google.com/file/d/1Zv721vZXAzVEpZ1RDg4c_Jd7DHyqBdZD/view?usp=drivesdk | P7: =HYPERLINK("https://drive.google.com/file/d/1Zv721vZXAzVEpZ1RDg4c_Jd7DHyqBdZD/view?usp=drivesdk","Regenerasi_Wardah Radhwa Hafizhah") -> Regenerasi_Wardah Radhwa Hafizhah | Q7: Document successfully created; Document successfully merged; PDF created; Manually run by labterpadu.unit.uns@gmail.com; Timestamp: Jun 12 2025 2:33 AM
A8: 45901 | B8: 45904 | C8: 567 | D8: Alfaira Nur Kamila | E8: 8973 | F8: MAN 2 Surakarta | G8: Akses | H8: Regenerasi Bakteri S.aureus | I8: Galuh Pratiwi | J8: 1 | K8: 300000 | L8: =J8*K8 -> 300000 | M8: Retno Hartati | N8: 1mCeHwdA4aWtwlbWPRRoe8jQ66fGqH2rS | O8: https://drive.google.com/file/d/1mCeHwdA4aWtwlbWPRRoe8jQ66fGqH2rS/view?usp=drivesdk | P8: =HYPERLINK("https://drive.google.com/file/d/1mCeHwdA4aWtwlbWPRRoe8jQ66fGqH2rS/view?usp=drivesdk","Regenerasi_Alfaira Nur Kamila") -> Regenerasi_Alfaira Nur Kamila | Q8: Document successfully created; Document successfully merged; PDF created; Manually run by labterpadu.unit.uns@gmail.com; Timestamp: Sep 4 2025 12:30 AM
A9: 45922 | B9: 45930 | C9: 616 | D9: Esti Margi Utami | E9: - | F9: SMA SEMESTA SEMARANG | G9: Tidak Akses | H9: Regenerasi Jamur | I9: Galuh Pratiwi | J9: 1 | K9: 300000 | L9: =J9*K9 -> 300000 | M9: Retno Hartati | N9: 11LC2kVe_labbfvLlBwFEWVDJNB9cx_kd | O9: https://drive.google.com/file/d/11LC2kVe_labbfvLlBwFEWVDJNB9cx_kd/view?usp=drivesdk | P9: =HYPERLINK("https://drive.google.com/file/d/11LC2kVe_labbfvLlBwFEWVDJNB9cx_kd/view?usp=drivesdk","Regenerasi_Esti Margi Utami") -> Regenerasi_Esti Margi Utami | Q9: Document successfully created; Document successfully merged; PDF created; Manually run by labterpadu.unit.uns@gmail.com; Timestamp: Sep 30 2025 12:36 AM

Sheet Fitokimia
A1: Tanggal Map Keluar | B1: Hari, Tanggal pembuatan rekap | C1: Agenda | D1: Nama | E1: NIM/NIP | F1: Fakultas/Univ | G1: Akses Lab | H1: Uji | I1: Analis | J1: Jumlah Sampel | K1: Harga per sampel | L1: Total Harga | M1: Pembuat Rekap | N1: Merged Doc ID - Fitokimia | O1: Merged Doc URL - Fitokimia | P1: Link to merged Doc - Fitokimia | Q1: Document Merge Status - Fitokimia
A2: 45805 | B2: 45810 | C2: 337 | D2: Sarah Albelita Purba | E2: I0522097 | F2: Teknik/Teknik Kimia | G2: Tidak Akses | H2: Screening Alkaloid dan Flavonoid | I2: Galuh Pratiwi | J2: 2 | K2: 60000 | L2: =J2*K2 -> 120000 | M2: Retno Hartati | N2: 1qqJsS7Dh2Uvv9YyFslfT_ehCTDxp9J3O | O2: https://drive.google.com/file/d/1qqJsS7Dh2Uvv9YyFslfT_ehCTDxp9J3O/view?usp=drivesdk | P2: =HYPERLINK("https://drive.google.com/file/d/1qqJsS7Dh2Uvv9YyFslfT_ehCTDxp9J3O/view?usp=drivesdk","Fitokimia_337") -> Fitokimia_337 | Q2: Document successfully created; Document successfully merged; PDF created; Manually run by labterpadu.unit.uns@gmail.com; Timestamp: Jun 2 2025 2:51 AM

Sheet Penggunaan Alat
A1: LAMPIRAN TARIF LAYANAN PENUNJANG AKADEMIK
A2: UNIVERSITAS SEBELAS MARET
A3: UPT LABORATORIUM TERPADU
A5: No. | B5: JENIS LAYANAN | G5: SATUAN | H5: TARIF (Rp)
A6: 1 | B6: LAYANAN PENGUJIAN KUALITAS AIR PER PARAMETER
B7: 1 | C7: Chemical Oxygen Demand (COD) | G7: Per sampel | H7: 100000
B8: 2 | C8: Biological Oxygen Demand (BOD) | G8: Per sampel | H8: 140000
B9: 3 | C9: Sulfida (S) | G9: Per sampel | H9: 150000
B10: 4 | C10: Sianida (CN) | G10: Per sampel | H10: 350000
B11: 5 | C11: Phenol | G11: Per sampel | H11: 300000
B12: 6 | C12: Dissolved Oxygen (DO) | G12: Per sampel | H12: 50000
B13: 7 | C13: Total Padatan Tersuspensi (TSS) | G13: Per sampel | H13: 100000
B14: 8 | C14: Total Padatan Terlarut (TDS) | G14: Per sampel | H14: 100000
B15: 9 | C15: Nitrit (NO2-N) | G15: Per sampel | H15: 90000
B16: 10 | C16: Nitrat (NO3-N) | G16: Per sampel | H16: 90000
B17: 11 | C17: Amonia Total (NH3-N) | G17: Per sampel | H17: 110000
B18: 12 | C18: orto-Phosphat (PO4) | G18: Per sampel | H18: 100000
... B54: 48 | C54: Perak (Ag) | G54: Per sampel | H54: 100000
A55: 2 | B55: LAYANAN PENGUJIAN KUALITAS UDARA PER PARAMETER
B56: 1 | C56: Ozon (O3) | G56: Per sampel | H56: 100000
B57: 2 | C57: Hidrogen sulfida (H2S) | G57: Per sampel | H57: 100000
B58: 3 | C58: Timbal (Pb) | G58: Per sampel | H58: 200000
B59: 4 | C59: Partikel tersuspensi total (TSP) | G59: Per sampel | H59: 200000
B60: 5 | C60: Amonia (NH3) | G60: Per sampel | H60: 150000
B61: 6 | C61: Carbon monoksida (CO) | G61: Per sampel | H61: 90000
B62: 7 | C62: Sulfur dioksida (SO2) | G62: Per sampel | H62: 150000
B63: 8 | C63: Nitrogen dioksida (NO2) | G63: Per sampel | H63: 100000
B65: Layanan pengujian Kebisingan
B66: 1 | C66: Tingkat kebisingan lingkungan | G66: Per sampel | H66: 100000
B67: Layanan pengujian lingkungan kerja
B68: 1 | C68: Intensitas pencahayaan | G68: Per sampel | H68: 100000
A70: 3 | B70: PENGUJIAN PARAMETER HALAL
B71: 1. | C71: Analisis DNA sd PCR | G71: Per sampel | H71: 600000
B72: 2. | C72: Analisis Alkohol kualitatif | G72: Per sampel | H72: 300000
B73: 3. | C73: Analisis Alkohol kuantitatif | G73: Per sampel | H73: 300000
A75: 4 | B75: PENGUJIAN PRODUK
B76: 1. | C76: Analisis APD (kain masker, kain hazmat)
C77: 1 | D77: Uji Anti bakteri APD | G77: Per sampel | H77: 500000
C78: 2 | D78: Uji kedap air APD | G78: Per sampel | H78: 150000
C79: 3 | D79: Uji kedap udara APD | G79: Per sampel | H79: 150000
...

Sheet Ekstraksi
A1: Tanggal Map Keluar | B1: Hari, Tanggal pembuatan rekap | C1: Agenda | D1: Nama | E1: NIM/NIP | F1: Fakultas/Univ | G1: Akses Lab | H1: Proses | I1: Analis | J1: Jumlah Sampel | K1: Harga per sampel | L1: Total Harga | M1: Pembuat Rekap | N1: Merged Doc ID - Ekstraksi | O1: Merged Doc URL - Ekstraksi | P1: Link to merged Doc - Ekstraksi | Q1: Document Merge Status - Ekstraksi
A2: 45670 | B2: 45714 | C2: 013 | D2: Joko Ariyanto | E2: T770210002 | F2: Pendidikan Biologi/UNS | G2: Tidak Akses | H2: Maserasi & EKstraksi | I2: Galuh Pratiwi | J2: 6 | K2: 500000 | L2: =J2*K2 -> 3000000 | M2: Retno Hartati | N2: 1uCAxmB5Y2TkcVhQf03UHQ3nl104pe2ph | O2: https://drive.google.com/file/d/1uCAxmB5Y2TkcVhQf03UHQ3nl104pe2ph/view?usp=drivesdk | P2: =HYPERLINK("https://drive.google.com/file/d/1uCAxmB5Y2TkcVhQf03UHQ3nl104pe2ph/view?usp=drivesdk","Ekstraksi_013") -> Ekstraksi_013 | Q2: Document successfully created; Document successfully merged; PDF created; Manually run by labterpadu.unit.uns@gmail.com; Timestamp: Feb 25 2025 10:03 PM

Sheet Organoleptik
A1: Tanggal Map Keluar | B1: Hari, Tanggal pembuatan rekap | C1: Agenda | D1: Nama | E1: NIM/NIP | F1: Fakultas/Univ | G1: Akses Lab | H1: Pengujian | I1: Analis | J1: Jumlah Sampel | K1: Harga per sampel | L1: Harga total | M1: Pembuat Rekap | N1: Merged Doc ID - Organoleptik | O1: Merged Doc URL - Organoleptik | P1: Link to merged Doc - Organoleptik | Q1: Document Merge Status - Organoleptik
A2: 45834 | B2: 45965 | C2: 436 | D2: Widya Mudyantini | E2: 197305051999032001 | F2: Biologi-FMIPA | G2: Tidak Akses | H2: Organoleptik | I2: Retno | J2: 3 | K2: 100000 | L2: =J2*K2 -> 300000 | M2: Retno | N2: 1fM9po5ZwdyrPXRQxsno2qdndXPeyCE5W | O2: https://drive.google.com/file/d/1fM9po5ZwdyrPXRQxsno2qdndXPeyCE5W/view?usp=drivesdk | P2: =HYPERLINK("https://drive.google.com/file/d/1fM9po5ZwdyrPXRQxsno2qdndXPeyCE5W/view?usp=drivesdk","Organoleptik_<Agenda>>") -> Organoleptik_<Agenda>> | Q2: Document successfully created; Document successfully merged; PDF created; Manually run by labterpadu.unit.uns@gmail.com; Timestamp: Nov 5 2025 12:00 AM

Sheet GC-MS
A1: Tanggal Map Keluar | B1: Hari, Tanggal pembuatan rekap | C1: Agenda | D1: Nama | E1: NIM/NIP | F1: Fakultas/Univ | G1: Akses Lab | H1: Instrument | I1: Operator | J1: Jumlah Sampel | K1: Harga per sampel | L1: Harga total | M1: Waktu retensi | N1: Persiapan instrument | O1: Preparasi sampel | P1: Blank | Q1: Pengukuran sampel | R1: Pengolahan data | S1: Mematikan instrument | T1: Total waktu pengerjaan | U1: Jumlah Syringe | V1: Harga_1 | W1: Total_1 | X1: Jumlah Whatman (50 k) / Nylon (30 k) | Y1: Harga_2 | Z1: Total_2 | AA1: Pelarut | AB1: Volume | AC1: Harga_3 | AD1: Total_3 | AE1: Total_Bahan | AF1: Pembuat Rekap | AG1: Merged Doc ID - Rekap GC-MS | AH1: Merged Doc URL - Rekap GC-MS | AI1: Link to merged Doc - Rekap GC-MS | AJ1: Document Merge Status - Rekap GC-MS
A2: 45520 | B2: 45531 | C2: 720 | D2: Nanda Dewi R | E2: 23175290A | F2: Farmasi/Universitas Setia Budi | G2: Tidak Akses | H2: GC-MS | I2: Dendy | J2: 1 | K2: 400000 | M2: 38 + 7 | N2: 60 | O2: 20 | P2: 45 | Q2: 45 | R2: 30 | S2: 60 | T2: =SUM(N2:S2) -> 260 | AF2: Retno H | AG2: 1YQu1FuyLYYFpQ5tlbxyPx2PVPInH-Ye8 | AH2: https://drive.google.com/file/d/1YQu1FuyLYYFpQ5tlbxyPx2PVPInH-Ye8/view?usp=drivesdk | AI2: =HYPERLINK("https://drive.google.com/file/d/1YQu1FuyLYYFpQ5tlbxyPx2PVPInH-Ye8/view?usp=drivesdk","GC-MS_Nanda Dewi R_720") -> GC-MS_Nanda Dewi R_720 | AJ2: Document successfully created; Document successfully merged; PDF created; Manually run by labterpadu.unit.uns@gmail.com; Timestamp: Nov 8 2024 2:27 AM
AG3: 1_ApHqvZC52h7o3wXMli_sun_ConK9Huw | AH3: https://drive.google.com/file/d/1_ApHqvZC52h7o3wXMli_sun_ConK9Huw/view?usp=drivesdk | AI3: =HYPERLINK("https://drive.google.com/file/d/1_ApHqvZC52h7o3wXMli_sun_ConK9Huw/view?usp=drivesdk","GC-MS_Contoh_7xx") -> GC-MS_Contoh_7xx | AJ3: Document successfully created; Document successfully merged; PDF created; Manually run by labterpadu.unit.uns@gmail.com; Timestamp: Nov 8 2024 2:27 AM
A4: 45589 | B4: 45607 | C4: 847 | D4: Mazlan | E4: T742208002 | F4: Pascasarjana | G4: Akses | H4: GC-MS | I4: Dendy | J4: 3 | K4: 400000 | M4: 70 + 15 | N4: 60 | O4: 60 | P4: 85 | Q4: 255 | R4: 90 | S4: 60 | T4: =SUM(N4:S4) -> 610 | U4: 3 | X4: 3 | AA4: n-heksana | AB4: 30 ml | AF4: Retno H | AG4: 1P9V0ZfzjrEUe4ja4Az1Tcbu5SuLJ3t26 | AH4: https://drive.google.com/file/d/1P9V0ZfzjrEUe4ja4Az1Tcbu5SuLJ3t26/view?usp=drivesdk | AI4: =HYPERLINK("https://drive.google.com/file/d/1P9V0ZfzjrEUe4ja4Az1Tcbu5SuLJ3t26/view?usp=drivesdk","GC-MS_Mazlan_847") -> GC-MS_Mazlan_847 | AJ4: Document successfully created; Document successfully merged; PDF created; Manually run by labterpadu.unit.uns@gmail.com; Timestamp: Nov 8 2024 2:33 AM
A5: 45590 | B5: 45607 | C5: 850 | D5: Nindy Samira Rahmi | E5: M0321049 | F5: Kimia/MIPA/UNS | G5: Akses | H5: GC-MS | I5: Dendy | J5: 1 | K5: 400000 | M5: 45 + 15 | N5: 60 | O5: - | P5: 60 | Q5: 60 | R5: 30 | S5: 60 | T5: =SUM(N5:S5) -> 270 | U5: 0 | X5: 0 | AA5: - | AB5: 0 | AF5: Retno H | AG5: 1gDuKlRNUq1dpYf_z2PlFvdkuI_bL_dZu | AH5: https://drive.google.com/file/d/1gDuKlRNUq1dpYf_z2PlFvdkuI_bL_dZu/view?usp=drivesdk | AI5: =HYPERLINK("https://drive.google.com/file/d/1gDuKlRNUq1dpYf_z2PlFvdkuI_bL_dZu/view?usp=drivesdk","GC-MS_Nindy Samira Rahmi _850") -> GC-MS_Nindy Samira Rahmi _850 | AJ5: Document successfully created; Document successfully merged; PDF created; Manually run by labterpadu.unit.uns@gmail.com; Timestamp: Nov 8 2024 2:30 AM
A6: 45589 | B6: 45611 | C6: 846 | D6: Halim Maylano | E6: K3321031 | F6: Pendidikan Kimia | G6: Akses | H6: GC-MS | I6: Dendy | J6: 4 | K6: 400000 | M6: 15 + 15 | N6: 60 | O6: 60 | P6: 30 | Q6: 120 | R6: 120 | S6: 60 | T6: =SUM(N6:S6) -> 450 | U6: 4 | X6: 3 | AA6: n-heksana | AB6: 30 ml | AF6: Retno H | AG6: 1RiuTuwmzo6O7qQAcJd-UKR7Doz5pAEiA | AH6: https://drive.google.com/file/d/1RiuTuwmzo6O7qQAcJd-UKR7Doz5pAEiA/view?usp=drivesdk | AI6: =HYPERLINK("https://drive.google.com/file/d/1RiuTuwmzo6O7qQAcJd-UKR7Doz5pAEiA/view?usp=drivesdk","GC-MS_Halim Maylano_846") -> GC-MS_Halim Maylano_846 | AJ6: Document successfully created; Document successfully merged; PDF created; Manually run by labterpadu.unit.uns@gmail.com; Timestamp: Nov 18 2024 12:36 AM
A7: 45617 | B7: 45630 | C7: 891 | D7: Mazlan | E7: T742208002 | F7: Pascasarjana | G7: Akses | H7: GC-MS | I7: Dendy | J7: 3 | K7: 400000 | M7: 70 + 15 | N7: 60 | O7: 60 | P7: 85 | Q7: 255 | R7: 90 | S7: 60 | T7: =SUM(N7:S7) -> 610 | U7: 3 | V7: 5000 | W7: =U7*V7 -> 15000 | X7: 3 | Y7: 50000 | Z7: =X7*Y7 -> 150000 | AA7: n-heksana | AB7: 30 | AC7: 1000 | AD7: =AB7*AC7 -> 30000 | AE7: =W7+Z7+AD7 -> 195000 | AF7: Retno H | AG7: 1YpE_i7Xo0aCEM7AauGKKeFcbalRV8ZV5 | AH7: https://drive.google.com/file/d/1YpE_i7Xo0aCEM7AauGKKeFcbalRV8ZV5/view?usp=drivesdk | AI7: =HYPERLINK("https://drive.google.com/file/d/1YpE_i7Xo0aCEM7AauGKKeFcbalRV8ZV5/view?usp=drivesdk","GC-MS_Mazlan_891") -> GC-MS_Mazlan_891 | AJ7: Document successfully created; Document successfully merged; PDF created; Manually run by labterpadu.unit.uns@gmail.com; Timestamp: Dec 3 2024 9:18 PM
A8: 45625 | B8: 45630 | C8: 896 | D8: Nindy Samira Rahmi | E8: M0321049 | F8: kimia/FMIPA/UNS | G8: Akses | H8: GC-MS | I8: Dendy | J8: 1 | K8: 400000 | M8: 45 + 15 | N8: 60 | O8: - | P8: 60 | Q8: 60 | R8: 30 | S8: 60 | T8: =SUM(N8:S8) -> 270 | U8: 1 | V8: 5000 | W8: =U8*V8 -> 5000 | X8: 1 | Y8: 50000 | Z8: =X8*Y8 -> 50000 | AA8: - | AB8: 0 | AC8: 0 | AD8: =AB8*AC8 -> 0 | AE8: =W8+Z8+AD8 -> 55000 | AF8: Retno H | AG8: 1htjZ1ZPf32I0KYns4PbS2upqYFeo3ZrO | AH8: https://drive.google.com/file/d/1htjZ1ZPf32I0KYns4PbS2upqYFeo3ZrO/view?usp=drivesdk | AI8: =HYPERLINK("https://drive.google.com/file/d/1htjZ1ZPf32I0KYns4PbS2upqYFeo3ZrO/view?usp=drivesdk","GC-MS_Nindy Samira Rahmi_896") -> GC-MS_Nindy Samira Rahmi_896 | AJ8: Document successfully created; Document successfully merged; PDF created; Manually run by labterpadu.unit.uns@gmail.com; Timestamp: Dec 3 2024 9:18 PM
A9: 45637 | B9: 45644 | C9: 928 | D9: Mardiana | E9: S062402001 | F9: Kimia/MIPA/UNS | G9: Akses | H9: GC-MS | I9: Dendy | J9: 1 | K9: 400000 | M9: 44 + 15 | N9: 60 | O9: 20 | P9: 60 | Q9: 60 | R9: 30 | S9: 60 | T9: =SUM(N9:S9) -> 290 | U9: 1 | V9: 3000 | W9: =U9*V9 -> 3000 | X9: 1 | Y9: 50000 | Z9: =X9*Y9 -> 50000 | AA9: n-heksana | AB9: 10 | AC9: 1000 | AD9: =AB9*AC9 -> 10000 | AE9: =W9+Z9+AD9 -> 63000 | AF9: Retno H | AG9: 1OSur_85z0JFkxMOOnZUm9iqq6CTw32h4 | AH9: https://drive.google.com/file/d/1OSur_85z0JFkxMOOnZUm9iqq6CTw32h4/view?usp=drivesdk | AI9: =HYPERLINK("https://drive.google.com/file/d/1OSur_85z0JFkxMOOnZUm9iqq6CTw32h4/view?usp=drivesdk","GC-MS_Mardiana_928") -> GC-MS_Mardiana_928 | AJ9: Document successfully created; Document successfully merged; PDF created; Manually run by labterpadu.unit.uns@gmail.com; Timestamp: Dec 18 2024 3:44 AM
A10: 45595 | B10: 45644 | C10: 854 | D10: Retno Duwi Hardini | E10: S062108003 | F10: S2-Kimia/FMIPA | G10: Akses | H10: GC-MS | I10: Dendy | J10: 8 | K10: 400000 | M10: 50 + 15 | N10: 60 | O10: 160 | P10: 65 | Q10: 65 | R10: 240 | S10: 60 | T10: =SUM(N10:S10) -> 650 | U10: 8 | V10: 3000 | W10: =U10*V10 -> 24000 | X10: 8 | Y10: 50000 | Z10: =X10*Y10 -> 400000 | AA10: n-heksana | AB10: 80 | AC10: 1000 | AD10: =AB10*AC10 -> 80000 | AE10: =W10+Z10+AD10 -> 504000 | AF10: Retno H | AG10: 13AB7gKofGw4LOMgQxOt4ayOHpOO82PJo | AH10: https://drive.google.com/file/d/13AB7gKofGw4LOMgQxOt4ayOHpOO82PJo/view?usp=drivesdk | AI10: =HYPERLINK("https://drive.google.com/file/d/13AB7gKofGw4LOMgQxOt4ayOHpOO82PJo/view?usp=drivesdk","GC-MS_Retno Duwi Hardini_854") -> GC-MS_Retno Duwi Hardini_854 | AJ10: Document successfully created; Document successfully merged; PDF created; Manually run by labterpadu.unit.uns@gmail.com; Timestamp: Dec 18 2024 3:44 AM
A11: 45649 | B11: 45650 | C11: 947 | D11: Mardiana | E11: S062402001 | F11: Kimia/MIPA/UNS | G11: Akses | H11: GC-MS | I11: Dendy & Widyan | J11: 4 | K11: 400000 | M11: 44 + 15 | N11: 60 | O11: 80 | P11: 60 | Q11: 240 | R11: 120 | S11: 60 | T11: =SUM(N11:S11) -> 620 | U11: 4 | V11: 3000 | W11: =U11*V11 -> 12000 | X11: 4 | Y11: 50000 | Z11: =X11*Y11 -> 200000 | AA11: n-heksana | AB11: 40 | AC11: 1000 | AD11: =AB11*AC11 -> 40000 | AE11: =W11+Z11+AD11 -> 252000 | AF11: Retno H | AG11: 16tH3cYjHPEUh7qYRPP7JHlD54KSDE2xi | AH11: https://drive.google.com/file/d/16tH3cYjHPEUh7qYRPP7JHlD54KSDE2xi/view?usp=drivesdk | AI11: =HYPERLINK("https://drive.google.com/file/d/16tH3cYjHPEUh7qYRPP7JHlD54KSDE2xi/view?usp=drivesdk","GC-MS_Mardiana_947") -> GC-MS_Mardiana_947 | AJ11: Document successfully created; Document successfully merged; PDF created; Manually run by labterpadu.unit.uns@gmail.com; Timestamp: Dec 23 2024 11:18 PM
A12: 45672 | B12: 45701 | C12: 19 | D12: Mazlan | E12: T742208002 | F12: Pascasarjana | G12: Akses | H12: GC-MS | I12: Dendy | J12: 3 | K12: 400000 | L12: =J12*K12 -> 1200000 | M12: 37 + 15 | N12: 60 | O12: 60 | P12: 52 | Q12: 156 | R12: 90 | S12: 60 | T12: =SUM(N12:S12) -> 478 | U12: 3 | V12: 3000 | W12: =U12*V12 -> 9000 | X12: 3 | Y12: 50000 | Z12: =X12*Y12 -> 150000 | AA12: - | AB12: 0 | AC12: 0 | AD12: 0 | AE12: =W12+Z12+AD12 -> 159000 | AF12: Retno H | AG12: 1mOiD4tWDsk9iCOri7zP9xQkpA8VmKO-f | AH12: https://drive.google.com/file/d/1mOiD4tWDsk9iCOri7zP9xQkpA8VmKO-f/view?usp=drivesdk | AI12: =HYPERLINK("https://drive.google.com/file/d/1mOiD4tWDsk9iCOri7zP9xQkpA8VmKO-f/view?usp=drivesdk","GC-MS_Mazlan_19") -> GC-MS_Mazlan_19 | AJ12: Document successfully created; Document successfully merged; PDF created; Manually run by labterpadu.unit.uns@gmail.com; Timestamp: Feb 16 2025 7:59 PM
A13: 45764 | B13: 45796 | C13: 210 | D13: Dyah Ayu Fitria Ningsih | E13: M0321019 | F13: S-1 Kimia/MIPA/UNS | G13: Akses | H13: GC-MS | I13: Roshid | J13: 1 | K13: 400000 | L13: =J13*K13 -> 400000 | M13: 60 + 15 | N13: 60 | O13: =J13*20 -> 20 | P13: 60 | Q13: =J13*(P13+15) -> 75 | R13: =J13*30 -> 30 | S13: 60 | T13: =SUM(N13:S13) -> 305 | U13: =J13 -> 1 | V13: 3000 | W13: =U13*V13 -> 3000 | X13: =U13 -> 1 | Y13: 50000 | Z13: =X13*Y13 -> 50000 | AA13: n-heksana | AB13: 15 | AC13: 1000 | AD13: =AB13*AC13 -> 15000 | AE13: =W13+Z13+AD13 -> 68000 | AF13: Retno H | AG13: 1ErZTPYI2lyPJx1aPcy67Tw45LPAsAt95 | AH13: https://drive.google.com/file/d/1ErZTPYI2lyPJx1aPcy67Tw45LPAsAt95/view?usp=drivesdk | AI13: =HYPERLINK("https://drive.google.com/file/d/1ErZTPYI2lyPJx1aPcy67Tw45LPAsAt95/view?usp=drivesdk","GC-MS_Dyah Ayu Fitria Ningsih_210") -> GC-MS_Dyah Ayu Fitria Ningsih_210 | AJ13: Document successfully created; Document successfully merged; PDF created; Manually run by labterpadu.unit.uns@gmail.com; Timestamp: May 18 2025 9:45 PM
A14: 45764 | B14: 45796 | C14: 211 | D14: Dyah Ayu Fitria Ningsih | E14: M0321020 | F14: S-1 Kimia/MIPA/UNS | G14: Akses | H14: GC-MS | I14: Roshid | J14: 1 | K14: 400000 | L14: =J14*K14 -> 400000 | M14: 48 + 15 | N14: 60 | O14: =J14*20 -> 20 | P14: 48 | Q14: =J14*(P14+15) -> 63 | R14: =J14*30 -> 30 | S14: 60 | T14: =SUM(N14:S14) -> 281 | U14: =J14 -> 1 | V14: 3000 | W14: =U14*V14 -> 3000 | X14: =U14 -> 1 | Y14: 50000 | Z14: =X14*Y14 -> 50000 | AA14: n-heksana | AB14: 15 | AC14: 1000 | AD14: =AB14*AC14 -> 15000 | AE14: =W14+Z14+AD14 -> 68000 | AF14: Retno H | AG14: 1xY-cDVLs87E-6eESqwuXvKDXC7V2j3bq | AH14: https://drive.google.com/file/d/1xY-cDVLs87E-6eESqwuXvKDXC7V2j3bq/view?usp=drivesdk | AI14: =HYPERLINK("https://drive.google.com/file/d/1xY-cDVLs87E-6eESqwuXvKDXC7V2j3bq/view?usp=drivesdk","GC-MS_Dyah Ayu Fitria Ningsih_211") -> GC-MS_Dyah Ayu Fitria Ningsih_211 | AJ14: Document successfully created; Document successfully merged; PDF created; Manually run by labterpadu.unit.uns@gmail.com; Timestamp: May 18 2025 9:45 PM
A15: 45769 | B15: 45796 | C15: 217 | D15: Sabella Vegasty | E15: S06230804 | F15: S-2 Kimia/MIPA/UNS | G15: Akses | H15: GC-MS | I15: Roshid | J15: 3 | K15: 400000 | L15: =J15*K15 -> 1200000 | M15: 57 + 15 | N15: 60 | O15: =J15*20 -> 60 | P15: 57 | Q15: =J15*(P15+15) -> 216 | R15: =J15*30 -> 90 | S15: 60 | T15: =SUM(N15:S15) -> 543 | U15: =J15 -> 3 | V15: 3000 | W15: =U15*V15 -> 9000 | X15: =U15 -> 3 | Y15: 50000 | Z15: =X15*Y15 -> 150000 | AA15: n-heksana | AB15: 45 | AC15: 1000 | AD15: =AB15*AC15 -> 45000 | AE15: =W15+Z15+AD15 -> 204000 | AF15: Retno H | AG15: 1H_COBmdEIwPWHe9j2iwNsLLOa8OLqWY1 | AH15: https://drive.google.com/file/d/1H_COBmdEIwPWHe9j2iwNsLLOa8OLqWY1/view?usp=drivesdk | AI15: =HYPERLINK("https://drive.google.com/file/d/1H_COBmdEIwPWHe9j2iwNsLLOa8OLqWY1/view?usp=drivesdk","GC-MS_Sabella Vegasty_217") -> GC-MS_Sabella Vegasty_217 | AJ15: Document successfully created; Document successfully merged; PDF created; Manually run by labterpadu.unit.uns@gmail.com; Timestamp: May 18 2025 9:45 PM
A16: 45772 | B16: 45796 | C16: 228 | D16: Citra Nurlaela R | E16: M0321014 | F16: S-1 Kimia/MIPA/UNS | G16: Akses | H16: GC-MS | I16: Roshid | J16: 1 | K16: 400000 | L16: =J16*K16 -> 400000 | M16: 56 + 15 | N16: 60 | O16: =J16*20 -> 20 | P16: 56 | Q16: =J16*(P16+15) -> 71 | R16: =J16*30 -> 30 | S16: 60 | T16: =SUM(N16:S16) -> 297 | U16: =J16 -> 1 | V16: 3000 | W16: =U16*V16 -> 3000 | X16: =U16 -> 1 | Y16: 50000 | Z16: =X16*Y16 -> 50000 | AA16: n-heksana | AB16: 15 | AC16: 1000 | AD16: =AB16*AC16 -> 15000 | AE16: =W16+Z16+AD16 -> 68000 | AF16: Retno H | AG16: 1S4RT8KtLq3Plu4UKMkk70X37ZbFr7epw | AH16: https://drive.google.com/file/d/1S4RT8KtLq3Plu4UKMkk70X37ZbFr7epw/view?usp=drivesdk | AI16: =HYPERLINK("https://drive.google.com/file/d/1S4RT8KtLq3Plu4UKMkk70X37ZbFr7epw/view?usp=drivesdk","GC-MS_Citra Nurlaela R_228") -> GC-MS_Citra Nurlaela R_228 | AJ16: Document successfully created; Document successfully merged; PDF created; Manually run by labterpadu.unit.uns@gmail.com; Timestamp: May 18 2025 9:45 PM
A17: 45804 | B17: 45813 | C17: 332 | D17: Layla Nadda Zabrina | E17: M0318035 | F17: Kimia/FMIPA/UNS | G17: Tidak Akses | H17: Gas Chromatography Mass Spectrometry (GC-MS) | I17: Roshid | J17: 1 | K17: 400000 | L17: =J17*K17 -> 400000 | M17: 65 + 15 | N17: 60 | O17: =J17*20 -> 20 | P17: 65 | Q17: =J17*(P17+15) -> 80 | R17: =J17*30 -> 30 | S17: 60 | T17: =SUM(N17:S17) -> 315 | U17: 1 | V17: 3000 | W17: =U17*V17 -> 3000 | X17: =U17 -> 1 | Y17: 50000 | Z17: =X17*Y17 -> 50000 | AA17: n-heksana | AB17: 10 | AC17: 1000 | AD17: =AB17*AC17 -> 10000 | AE17: =W17+Z17+AD17 -> 63000 | AF17: Retno H | AG17: 1UenJrawKMtox-ofjff6S604owWZ1B56t | AH17: https://drive.google.com/file/d/1UenJrawKMtox-ofjff6S604owWZ1B56t/view?usp=drivesdk | AI17: =HYPERLINK("https://drive.google.com/file/d/1UenJrawKMtox-ofjff6S604owWZ1B56t/view?usp=drivesdk","GC-MS_Layla Nadda Zabrina_332") -> GC-MS_Layla Nadda Zabrina_332 | AJ17: Document successfully created; Document successfully merged; PDF created; Manually run by labterpadu.unit.uns@gmail.com; Timestamp: Jun 5 2025 3:01 AM
A18: 45811 | B18: 45813 | C18: 361 | D18: Yulia Sandi Iswara | E18: M0321079 | F18: Kimia/FMIPA/UNS | G18: Tidak Akses | H18: GC-MS | I18: Roshid | J18: 1 | K18: 400000 | L18: =J18*K18 -> 400000 | M18: 77 + 15 | N18: 60 | O18: 20 | P18: 77 | Q18: =J18*(P18+15) -> 92 | R18: =J18*30 -> 30 | S18: 60 | T18: =SUM(N18:S18) -> 339 | U18: 2 | V18: 3000 | W18: =U18*V18 -> 6000 | X18: =U18 -> 2 | Y18: 50000 | Z18: =X18*Y18 -> 100000 | AA18: aseton | AB18: 20 | AC18: 1000 | AD18: =AB18*AC18 -> 20000 | AE18: =W18+Z18+AD18 -> 126000 | AF18: Retno H | AG18: 1ofHlEOZPKxmskCi7xIS1-udo9GIkY9V4 | AH18: https://drive.google.com/file/d/1ofHlEOZPKxmskCi7xIS1-udo9GIkY9V4/view?usp=drivesdk | AI18: =HYPERLINK("https://drive.google.com/file/d/1ofHlEOZPKxmskCi7xIS1-udo9GIkY9V4/view?usp=drivesdk","GC-MS_Yulia Sandi Iswara_361") -> GC-MS_Yulia Sandi Iswara_361 | AJ18: Document successfully created; Document successfully merged; PDF created; Manually run by labterpadu.unit.uns@gmail.com; Timestamp: Jun 11 2025 12:51 AM
A19: 45797 | B19: 45813 | C19: 277 | D19: Wanda Khairunnisa Wibowo | E19: M0623077 | F19: S1 Farmasi/FMIPA/UNS | G19: Tidak Akses | H19: GC-MS | I19: Roshid | J19: 3 | K19: 400000 | L19: =J19*K19 -> 1200000 | M19: 65 + 15 | N19: 60 | O19: 20 | P19: 65 | Q19: =J19*(P19+15) -> 240 | R19: =J19*30 -> 90 | S19: 60 | T19: =SUM(N19:S19) -> 535 | U19: 3 | V19: 3000 | W19: =U19*V19 -> 9000 | X19: 3 | Y19: 30000 | Z19: =X19*Y19 -> 90000 | AA19: n-heksana | AB19: 30 | AC19: 1000 | AD19: =AB19*AC19 -> 30000 | AE19: =W19+Z19+AD19 -> 129000 | AF19: Retno H | AG19: 1AnqqmrYH1TH1md8DI44BvdJr64MTIvV5 | AH19: https://drive.google.com/file/d/1AnqqmrYH1TH1md8DI44BvdJr64MTIvV5/view?usp=drivesdk | AI19: =HYPERLINK("https://drive.google.com/file/d/1AnqqmrYH1TH1md8DI44BvdJr64MTIvV5/view?usp=drivesdk","GC-MS_Wanda Khairunnisa Wibowo_277") -> GC-MS_Wanda Khairunnisa Wibowo_277 | AJ19: Document successfully created; Document successfully merged; PDF created; Manually run by labterpadu.unit.uns@gmail.com; Timestamp: Jun 11 2025 5:55 AM
A20: 45812 | B20: 45821 | C20: 370 | D20: Mazlan | E20: T742208002 | F20: Pascasarjana | G20: Akses | H20: GC-MS | I20: Roshid | J20: 3 | K20: 400000 | L20: =J20*K20 -> 1200000 | M20: 36+15 | N20: 60 | O20: 20 | P20: 36 | Q20: =J20*(P20+15) -> 153 | R20: =J20*30 -> 90 | S20: 60 | T20: =SUM(N20:S20) -> 419 | U20: 3 | V20: 3000 | W20: =U20*V20 -> 9000 | X20: 3 | Y20: 50000 | Z20: =X20*Y20 -> 150000 | AA20: n-heksana | AB20: 30 | AC20: 1000 | AD20: =AB20*AC20 -> 30000 | AE20: =W20+Z20+AD20 -> 189000 | AF20: Retno H | AG20: 1-EZo-L_qnh9wIxwtlQzhG1T7LadeDfEY | AH20: https://drive.google.com/file/d/1-EZo-L_qnh9wIxwtlQzhG1T7LadeDfEY/view?usp=drivesdk | AI20: =HYPERLINK("https://drive.google.com/file/d/1-EZo-L_qnh9wIxwtlQzhG1T7LadeDfEY/view?usp=drivesdk","GC-MS_Mazlan_370") -> GC-MS_Mazlan_370 | AJ20: Document successfully created; Document successfully merged; PDF created; Manually run by labterpadu.unit.uns@gmail.com; Timestamp: Jun 15 2025 11:04 PM
A21: 45825 | B21: 45827 | C21: 410 | D21: Layla Nadda Zabrina | E21: M0318035 | F21: S-1 Kimia/MIPA/UNS | G21: Tidak Akses | H21: GC-MS | I21: Roshid | J21: 2 | K21: 400000 | L21: =J21*K21 -> 800000 | M21: 65+15 | N21: 60 | O21: 20 | P21: 65 | Q21: =J21*(P21+15) -> 160 | R21: =J21*30 -> 60 | S21: 60 | T21: =SUM(N21:S21) -> 425 | U21: 2 | V21: 3000 | W21: =U21*V21 -> 6000 | X21: 2 | Y21: 30000 | Z21: =X21*Y21 -> 60000 | AA21: n-heksana | AB21: 10 | AC21: 1000 | AD21: =AB21*AC21 -> 10000 | AE21: =W21+Z21+AD21 -> 76000 | AF21: Retno H | AG21: 1_REV0hn2OS6CfwHaLKDopwTW8vtEOx1s | AH21: https://drive.google.com/file/d/1_REV0hn2OS6CfwHaLKDopwTW8vtEOx1s/view?usp=drivesdk | AI21: =HYPERLINK("https://drive.google.com/file/d/1_REV0hn2OS6CfwHaLKDopwTW8vtEOx1s/view?usp=drivesdk","GC-MS_Layla Nadda Zabrina_410") -> GC-MS_Layla Nadda Zabrina_410 | AJ21: Document successfully created; Document successfully merged; PDF created; Manually run by labterpadu.unit.uns@gmail.com; Timestamp: Jun 19 2025 11:09 PM
A22: 45827 | B22: 45827 | C22: 405 | D22: Rohula Utami | E22: T652308006 | F22: S-3 Ilmu Pertanian/FP/UNS | G22: Tidak Akses | H22: GC-MS | I22: Roshid | J22: 6 | K22: 400000 | L22: =J22*K22 -> 2400000 | M22: 50+15 | N22: 60 | O22: 20 | P22: 50 | Q22: =J22*(P22+15) -> 390 | R22: =J22*30 -> 180 | S22: 60 | T22: =SUM(N22:S22) -> 760 | U22: 5 | V22: 3000 | W22: =U22*V22 -> 15000 | X22: 5 | Y22: 30000 | Z22: =X22*Y22 -> 150000 | AA22: etanol | AB22: 60 | AC22: 1000 | AD22: =AB22*AC22 -> 60000 | AE22: =W22+Z22+AD22 -> 225000 | AF22: Retno H | AG22: 1kGc-qh8RxpVi7e50Tat5TX_4F-MD35yX | AH22: https://drive.google.com/file/d/1kGc-qh8RxpVi7e50Tat5TX_4F-MD35yX/view?usp=drivesdk | AI22: =HYPERLINK("https://drive.google.com/file/d/1kGc-qh8RxpVi7e50Tat5TX_4F-MD35yX/view?usp=drivesdk","GC-MS_Rohula Utami_405") -> GC-MS_Rohula Utami_405 | AJ22: Document successfully created; Document successfully merged; PDF created; Manually run by labterpadu.unit.uns@gmail.com; Timestamp: Jun 19 2025 11:09 PM
A23: 45827 | B23: 45827 | C23: 422 | D23: Adelisa Monica Permadani | E23: K3322003 | F23: S-1 Pendidikan Kimia/FKIP/UNS | G23: Akses | H23: GC-MS | I23: Roshid | J23: 3 | K23: 400000 | L23: =J23*K23 -> 1200000 | M23: 62+15 | N23: 60 | O23: 20 | P23: 62 | Q23: =J23*(P23+15) -> 231 | R23: =J23*30 -> 90 | S23: 60 | T23: =SUM(N23:S23) -> 523 | U23: 3 | V23: 3000 | W23: =U23*V23 -> 9000 | X23: 3 | Y23: 30000 | Z23: =X23*Y23 -> 90000 | AA23: n-heksana | AB23: 30 | AC23: 1000 | AD23: =AB23*AC23 -> 30000 | AE23: =W23+Z23+AD23 -> 129000 | AF23: Retno H | AG23: 1eOcViftL4I9OUANbnZ_1NadcchR3Xtcc | AH23: https://drive.google.com/file/d/1eOcViftL4I9OUANbnZ_1NadcchR3Xtcc/view?usp=drivesdk | AI23: =HYPERLINK("https://drive.google.com/file/d/1eOcViftL4I9OUANbnZ_1NadcchR3Xtcc/view?usp=drivesdk","GC-MS_Adelisa Monica Permadani_422") -> GC-MS_Adelisa Monica Permadani_422 | AJ23: Document successfully created; Document successfully merged; PDF created; Manually run by labterpadu.unit.uns@gmail.com; Timestamp: Jun 19 2025 11:09 PM
A24: 45845 | B24: 45847 | C24: 465 | D24: Muhamad Fajrianor Lawi | E24: H0721096 | F24: S-1 Agroteknologi/ FP/ UNS | G24: Akses | H24: GC-MS | I24: Roshid | J24: 4 | K24: 400000 | L24: =J24*K24 -> 1600000 | M24: 61+15 | N24: 60 | O24: 20 | P24: 61 | Q24: =J24*(P24+15) -> 304 | R24: =J24*30 -> 120 | S24: 60 | T24: =SUM(N24:S24) -> 625 | U24: 4 | V24: 3000 | W24: =U24*V24 -> 12000 | X24: 4 | Y24: 30000 | Z24: =X24*Y24 -> 120000 | AA24: etanol | AB24: 30 | AC24: 1000 | AD24: =AB24*AC24 -> 30000 | AE24: =W24+Z24+AD24 -> 162000 | AF24: Retno H | AG24: 1EK2XEnuOsQPy_qjqUM_hYIp9HdEef1vu | AH24: https://drive.google.com/file/d/1EK2XEnuOsQPy_qjqUM_hYIp9HdEef1vu/view?usp=drivesdk | AI24: =HYPERLINK("https://drive.google.com/file/d/1EK2XEnuOsQPy_qjqUM_hYIp9HdEef1vu/view?usp=drivesdk","GC-MS_Muhamad Fajrianor Lawi_465") -> GC-MS_Muhamad Fajrianor Lawi_465 | AJ24: Document successfully created; Document successfully merged; PDF created; Manually run by labterpadu.unit.uns@gmail.com; Timestamp: Jul 14 2025 4:42 AM
A25: 45849 | B25: 45849 | C25: 476 | D25: Dwi Ardiana Setyawardhani | E25: 197301311998022001 | F25: Teknik kimia / Fakultas teknik/UNS | G25: Tidak Akses | H25: GC-MS | I25: Roshid | J25: 3 | K25: 400000 | L25: =J25*K25 -> 1200000 | M25: 66+15 | N25: 60 | O25: 20 | P25: 66 | Q25: =J25*(P25+15) -> 243 | R25: =J25*30 -> 90 | S25: 60 | T25: =SUM(N25:S25) -> 539 | U25: 3 | V25: 3000 | W25: =U25*V25 -> 9000 | X25: 3 | Y25: 30000 | Z25: =X25*Y25 -> 90000 | AA25: etanol | AB25: 25 | AC25: 1000 | AD25: =AB25*AC25 -> 25000 | AE25: =W25+Z25+AD25 -> 124000 | AF25: Retno H | AG25: 1pGQ__eSCxKLBcmVq2hyVgvNSXFYav3ds | AH25: https://drive.google.com/file/d/1pGQ__eSCxKLBcmVq2hyVgvNSXFYav3ds/view?usp=drivesdk | AI25: =HYPERLINK("https://drive.google.com/file/d/1pGQ__eSCxKLBcmVq2hyVgvNSXFYav3ds/view?usp=drivesdk","GC-MS_Dwi Ardiana Setyawardhani_476") -> GC-MS_Dwi Ardiana Setyawardhani_476 | AJ25: Document successfully created; Document successfully merged; PDF created; Manually run by labterpadu.unit.uns@gmail.com; Timestamp: Jul 14 2025 4:43 AM
A26: 45860 | B26: 45868 | C26: 490 | D26: M. Alkindi Sulthan Zhafran S | E26: D200210181 | F26: Teknik Mesin / Teknik / Universitas Muhammadiyah Surakarta | G26: Tidak Akses | H26: GC-MS | I26: Roshid | J26: 2 | K26: 500000 | L26: =J26*K26 -> 1000000 | M26: 72+15 | N26: 60 | O26: 20 | P26: 72 | Q26: =J26*(P26+15) -> 174 | R26: =J26*30 -> 60 | S26: 60 | T26: =SUM(N26:S26) -> 446 | U26: 2 | V26: 3000 | W26: =U26*V26 -> 6000 | X26: 2 | Y26: 30000 | Z26: =X26*Y26 -> 60000 | AA26: n-heksana | AB26: 20 | AC26: 1000 | AD26: =AB26*AC26 -> 20000 | AE26: =W26+Z26+AD26 -> 86000 | AF26: Retno H | AG26: 1Qr16cQnvXb8W5g4PB_J7x_yrAlPXhOPR | AH26: https://drive.google.com/file/d/1Qr16cQnvXb8W5g4PB_J7x_yrAlPXhOPR/view?usp=drivesdk | AI26: =HYPERLINK("https://drive.google.com/file/d/1Qr16cQnvXb8W5g4PB_J7x_yrAlPXhOPR/view?usp=drivesdk","GC-MS_M. Alkindi Sulthan Zhafran S_490") -> GC-MS_M. Alkindi Sulthan Zhafran S_490 | AJ26: Document successfully created; Document successfully merged; PDF created; Manually run by labterpadu.unit.uns@gmail.com; Timestamp: Aug 5 2025 9:26 PM
A27: 45863 | B27: 45869 | C27: 504 | D27: Prof Dr Dwi Ardiana Setyawardhani | E27: 197301311998022001 | F27: Teknik kimia/Fak Teknik/UNS | G27: Tidak Akses | H27: GC-MS | I27: Roshid | J27: 8 | K27: 400000 | L27: =J27*K27 -> 3200000 | M27: 66+15 | N27: 60 | O27: 20 | P27: 66 | Q27: =J27*(P27+15) -> 648 | R27: =J27*30 -> 240 | S27: 60 | T27: =SUM(N27:S27) -> 1094 | U27: 8 | V27: 3000 | W27: =U27*V27 -> 24000 | X27: 8 | Y27: 30000 | Z27: =X27*Y27 -> 240000 | AA27: etanol | AB27: 80 | AC27: 1000 | AD27: =AB27*AC27 -> 80000 | AE27: =W27+Z27+AD27 -> 344000 | AF27: Retno H | AG27: 1PZtXDTDohq41_OA0xOl5PwEoChGerC1z | AH27: https://drive.google.com/file/d/1PZtXDTDohq41_OA0xOl5PwEoChGerC1z/view?usp=drivesdk | AI27: =HYPERLINK("https://drive.google.com/file/d/1PZtXDTDohq41_OA0xOl5PwEoChGerC1z/view?usp=drivesdk","GC-MS_Prof Dr Dwi Ardiana Setyawardhani _504") -> GC-MS_Prof Dr Dwi Ardiana Setyawardhani _504 | AJ27: Document successfully created; Document successfully merged; PDF created; Manually run by labterpadu.unit.uns@gmail.com; Timestamp: Aug 5 2025 9:27 PM
A28: 45868 | B28: 45870 | C28: 508 | D28: Litaskuri S.Nur.H | E28: SC1008 | F28: Farmasi/Farmasi/STIKES Mambaul Ulum Surakarta | G28: Tidak Akses | H28: GC-MS | I28: Roshid | J28: 1 | K28: 500000 | L28: =J28*K28 -> 500000 | M28: 55+15 | N28: 60 | O28: 20 | P28: 55 | Q28: =J28*(P28+15) -> 70 | R28: =J28*30 -> 30 | S28: 60 | T28: =SUM(N28:S28) -> 295 | U28: 1 | V28: 3000 | W28: =U28*V28 -> 3000 | X28: 1 | Y28: 30000 | Z28: =X28*Y28 -> 30000 | AA28: etanol | AB28: 10 | AC28: 1000 | AD28: =AB28*AC28 -> 10000 | AE28: =W28+Z28+AD28 -> 43000 | AF28: Retno H | AG28: 1PcEP5LjYY3S1zKbCF-pbxruzZQciiETK | AH28: https://drive.google.com/file/d/1PcEP5LjYY3S1zKbCF-pbxruzZQciiETK/view?usp=drivesdk | AI28: =HYPERLINK("https://drive.google.com/file/d/1PcEP5LjYY3S1zKbCF-pbxruzZQciiETK/view?usp=drivesdk","GC-MS_Litaskuri S.Nur.H_508") -> GC-MS_Litaskuri S.Nur.H_508 | AJ28: Document successfully created; Document successfully merged; PDF created; Manually run by labterpadu.unit.uns@gmail.com; Timestamp: Aug 5 2025 9:27 PM
A29: 45870 | B29: 45870 | C29: 512 | D29: Vito Bintang Saputra | E29: M0321076 | F29: Kimia/MIPA/UNS | G29: Tidak Akses | H29: GC-MS | I29: Roshid | J29: 1 | K29: 400000 | L29: =J29*K29 -> 400000 | M29: 35+15 | N29: 60 | O29: 20 | P29: 35 | Q29: =J29*(P29+15) -> 50 | R29: =J29*30 -> 30 | S29: 60 | T29: =SUM(N29:S29) -> 255 | U29: 1 | V29: 3000 | W29: =U29*V29 -> 3000 | X29: 1 | Y29: 30000 | Z29: =X29*Y29 -> 30000 | AA29: etanol | AB29: 10 | AC29: 1000 | AD29: =AB29*AC29 -> 10000 | AE29: =W29+Z29+AD29 -> 43000 | AF29: Retno H | AG29: 12pS2Talcs6P4Ij_S-5oEtG8QaV32r-t- | AH29: https://drive.google.com/file/d/12pS2Talcs6P4Ij_S-5oEtG8QaV32r-t-/view?usp=drivesdk | AI29: =HYPERLINK("https://drive.google.com/file/d/12pS2Talcs6P4Ij_S-5oEtG8QaV32r-t-/view?usp=drivesdk","GC-MS_Vito Bintang Saputra_512") -> GC-MS_Vito Bintang Saputra_512 | AJ29: Document successfully created; Document successfully merged; PDF created; Manually run by labterpadu.unit.uns@gmail.com; Timestamp: Aug 5 2025 9:27 PM
A30: 45929 | B30: 45932 | C30: 644 | D30: PT. Indo Acidatama Tbk. | E30: - | F30: PT. Indo Acidatama Tbk. | G30: Tidak Akses | H30: GC-MS | I30: Roshid | J30: 1 | K30: 500000 | L30: =J30*K30 -> 500000 | M30: 30+15 | N30: 60 | O30: 20 | P30: 35 | Q30: =J30*(P30+15) -> 50 | R30: =J30*30 -> 30 | S30: 60 | T30: =SUM(N30:S30) -> 255 | U30: 1 | V30: 3000 | W30: =U30*V30 -> 3000 | X30: 1 | Y30: 30000 | Z30: =X30*Y30 -> 30000 | AE30: =W30+Z30+AD30 -> 33000 | AF30: Retno H | AG30: 1feIBsqmQwQ6803_PZ7NkE3pqI4ifwzFN | AH30: https://drive.google.com/file/d/1feIBsqmQwQ6803_PZ7NkE3pqI4ifwzFN/view?usp=drivesdk | AI30: =HYPERLINK("https://drive.google.com/file/d/1feIBsqmQwQ6803_PZ7NkE3pqI4ifwzFN/view?usp=drivesdk","GC-MS_PT. Indo Acidatama Tbk._644") -> GC-MS_PT. Indo Acidatama Tbk._644 | AJ30: Document successfully created; Document successfully merged; PDF created; Manually run by labterpadu.unit.uns@gmail.com; Timestamp: Oct 9 2025 4:18 AM
A31: 45895 | B31: 45951 | C31: 561 | D31: Putri Aisyah Ali | E31: K3322080 | F31: P Kimia/FKIP/UNS | G31: Tidak Akses | H31: GC-MS | I31: Roshid | J31: 4 | K31: 400000 | L31: =J31*K31 -> 1600000 | M31: 30+15 | N31: 60 | O31: 20 | P31: 35 | Q31: =J31*(P31+15) -> 200 | R31: =J31*30 -> 120 | S31: 60 | T31: =SUM(N31:S31) -> 495 | U31: 4 | V31: 3000 | W31: =U31*V31 -> 12000 | X31: 4 | Y31: 30000 | Z31: =X31*Y31 -> 120000 | AE31: =W31+Z31+AD31 -> 132000 | AF31: Retno H | AG31: 1Y3o3UkkkV-ErdF-GfQIT7nQITnzz6PIJ | AH31: https://drive.google.com/file/d/1Y3o3UkkkV-ErdF-GfQIT7nQITnzz6PIJ/view?usp=drivesdk | AI31: =HYPERLINK("https://drive.google.com/file/d/1Y3o3UkkkV-ErdF-GfQIT7nQITnzz6PIJ/view?usp=drivesdk","GC-MS_Putri Aisyah Ali_561") -> GC-MS_Putri Aisyah Ali_561 | AJ31: Document successfully created; Document successfully merged; PDF created; Manually run by labterpadu.unit.uns@gmail.com; Timestamp: Oct 21 2025 12:21 AM
